Workbook

Sheet READ.ME

Sheet CombinedData
A1: PRES | B1: Rat_number | C1: Stroke_status | D1: Blinding_group | E1: Gender | F1: Weight | G1: Age | H1: Dominant paw | I1: Time in box | J1: Number of trainings | K1: First trial success_ALL | L1: Total success_ALL | M1: Total pellet to box_ALL | N1: Total fail_ALL | O1: Total grasps_ALL | P1: First trial success | Q1: Total success | R1: Total pellet to box | S1: Total fail | T1: Total grasps
B2: R1 | C2: Baseline | D2: 1 | E2: F | K2: =RawData_Rat1!E36 -> 5 | L2: =RawData_Rat1!D37 -> 9 | M2: =RawData_Rat1!D39 -> 3 | N2: =RawData_Rat1!D38 -> 14 | O2: =RawData_Rat1!D40 -> 23 | P2: =RawData_Rat1!E36 -> 5 | Q2: =RawData_Rat1!E37 -> 9 | R2: =RawData_Rat1!E39 -> 3 | S2: =RawData_Rat1!E38 -> 11 | T2: =RawData_Rat1!E40 -> 20
B3: R1 | C3: Post | D3: 1 | E3: F | K3: =RawData_Rat1!D76 -> 0 | L3: =RawData_Rat1!D77 -> 0 | M3: =RawData_Rat1!D79 -> 0 | N3: =RawData_Rat1!D78 -> 0 | O3: =RawData_Rat1!D80 -> 0 | P3: =RawData_Rat1!E76 -> 0 | Q3: =RawData_Rat1!E77 -> 0 | R3: =RawData_Rat1!E79 -> 0 | S3: =RawData_Rat1!E78 -> 0 | T3: =RawData_Rat1!E80 -> 0
B4: R2 | C4: Baseline | D4: 1 | E4: F | K4: =RawData_Rat2!D36 -> 0 | L4: =RawData_Rat2!D37 -> 0 | M4: =RawData_Rat2!D39 -> 0 | N4: =RawData_Rat2!D38 -> 5 | O4: =RawData_Rat2!D40 -> 5 | P4: =RawData_Rat2!E36 -> 0 | Q4: =RawData_Rat2!E37 -> 0 | R4: =RawData_Rat2!E39 -> 0 | S4: =RawData_Rat2!E38 -> 5 | T4: =RawData_Rat2!E40 -> 5
B5: R2 | C5: Post | D5: 1 | E5: F | K5: =RawData_Rat2!D76 -> 0 | L5: =RawData_Rat2!D77 -> 0 | M5: =RawData_Rat2!D79 -> 0 | N5: =RawData_Rat2!D78 -> 0 | O5: =RawData_Rat2!D80 -> 0 | P5: =RawData_Rat2!E76 -> 0 | Q5: =RawData_Rat2!E77 -> 0 | R5: =RawData_Rat2!E79 -> 0 | S5: =RawData_Rat2!E78 -> 0 | T5: =RawData_Rat2!E80 -> 0
B6: R3 | C6: Baseline | D6: 2 | E6: M | K6: =RawData_Rat3!D34 -> 0 | L6: =RawData_Rat3!D35 -> 0 | M6: =RawData_Rat3!D37 -> 0 | N6: =RawData_Rat3!D36 -> 0 | O6: =RawData_Rat3!D38 -> 0 | P6: =RawData_Rat3!E34 -> 0 | Q6: =RawData_Rat3!E35 -> 0 | R6: =RawData_Rat3!E37 -> 0 | S6: =RawData_Rat3!E36 -> 0 | T6: =RawData_Rat3!E38 -> 0
B7: R3 | C7: Post | D7: 2 | E7: M | K7: =RawData_Rat3!D73 -> 0 | L7: =RawData_Rat3!D74 -> 0 | M7: =RawData_Rat3!D75 -> 0 | N7: =RawData_Rat3!D76 -> 0 | O7: =RawData_Rat3!D77 -> 0 | P7: =RawData_Rat3!E73 -> 0 | Q7: =RawData_Rat3!E74 -> 0 | R7: =RawData_Rat3!E75 -> 0 | S7: =RawData_Rat3!E76 -> 0 | T7: =RawData_Rat3!E77 -> 0
A8: 884343 | B8: R4 | C8: Baseline | D8: 1 | E8: M | K8: =RawData_Rat4!D36 -> 19 | L8: =RawData_Rat4!D37 -> 24 | M8: =RawData_Rat4!D39 -> 0 | N8: =RawData_Rat4!D38 -> 7 | O8: =RawData_Rat4!D40 -> 31 | P8: =RawData_Rat4!E36 -> 11 | Q8: =RawData_Rat4!E37 -> 15 | R8: =RawData_Rat4!E39 -> 0 | S8: =RawData_Rat4!E38 -> 5 | T8: =RawData_Rat4!E40 -> 20
A9: 884343 | B9: R4 | C9: Post | D9: 1 | E9: M | K9: =RawData_Rat4!D75 -> 10 | L9: =RawData_Rat4!D76 -> 12 | M9: =RawData_Rat4!D77 -> 18 | N9: =RawData_Rat4!D78 -> 5 | O9: =RawData_Rat4!D79 -> 30 | P9: =RawData_Rat4!E75 -> 7 | Q9: =RawData_Rat4!E76 -> 9 | R9: =RawData_Rat4!E77 -> 11 | S9: =RawData_Rat4!E78 -> 4 | T9: =RawData_Rat4!E79 -> 20
B10: R5 | C10: Baseline | D10: 2 | E10: F | K10: =RawData_Rat5!D35 -> 4 | L10: =RawData_Rat5!D36 -> 6 | M10: =RawData_Rat5!D38 -> 1 | N10: =RawData_Rat5!D37 -> 21 | O10: =RawData_Rat5!D39 -> 27 | P10: =RawData_Rat5!E35 -> 2 | Q10: =RawData_Rat5!E36 -> 3 | R10: =RawData_Rat5!E38 -> 1 | S10: =RawData_Rat5!E37 -> 15 | T10: =RawData_Rat5!E39 -> 18
B11: R5 | C11: Post | D11: 2 | E11: F | K11: =RawData_Rat5!D75 -> 0 | L11: =RawData_Rat5!D76 -> 0 | M11: =RawData_Rat5!D78 -> 0 | N11: =RawData_Rat5!D77 -> 5 | O11: =RawData_Rat5!D79 -> 5 | P11: =RawData_Rat5!E75 -> 0 | Q11: =RawData_Rat5!E76 -> 0 | R11: =RawData_Rat5!E78 -> 0 | S11: =RawData_Rat5!E77 -> 5 | T11: =RawData_Rat5!E79 -> 5
B12: R6 | C12: Baseline | D12: 1 | E12: F | K12: =RawData_Rat6!D36 -> 4 | L12: =RawData_Rat6!D37 -> 7 | M12: =RawData_Rat6!D39 -> 3 | N12: =RawData_Rat6!D38 -> 22 | O12: =RawData_Rat6!D40 -> 29 | P12: =RawData_Rat6!E36 -> 2 | Q12: =RawData_Rat6!E37 -> 4 | R12: =RawData_Rat6!E39 -> 2 | S12: =RawData_Rat6!E38 -> 16 | T12: =RawData_Rat6!E40 -> 20
B13: R6 | C13: Post | D13: 1 | E13: F | K13: =RawData_Rat6!D76 -> 4 | L13: =RawData_Rat6!D77 -> 6 | M13: =RawData_Rat6!D79 -> 2 | N13: =RawData_Rat6!D78 -> 24 | O13: =RawData_Rat6!D80 -> 30 | P13: =RawData_Rat6!E76 -> 2 | Q13: =RawData_Rat6!E77 -> 3 | R13: =RawData_Rat6!E79 -> 1 | S13: =RawData_Rat6!E78 -> 17 | T13: =RawData_Rat6!E80 -> 20
B14: R7 | C14: Baseline | D14: 4 | E14: M | H14: Left paw | K14: =RawData_Rat7!$D$36 -> 4 | L14: =RawData_Rat7!$D$37 -> 6 | M14: =RawData_Rat7!$D$39 -> 0 | N14: =RawData_Rat7!$D$38 -> 25 | O14: =RawData_Rat7!$D$40 -> 31 | P14: =RawData_Rat7!E36 -> 2 | Q14: =RawData_Rat7!E37 -> 2 | R14: =RawData_Rat7!E39 -> 0 | S14: =RawData_Rat7!E38 -> 18 | T14: =RawData_Rat7!E40 -> 20
B15: R7 | C15: Post | D15: 4 | E15: M | H15: Left paw | K15: =RawData_Rat7!$D$76 -> 7 | L15: =RawData_Rat7!$D$77 -> 11 | M15: =RawData_Rat7!$D$79 -> 0 | N15: =RawData_Rat7!$D$78 -> 20 | O15: =RawData_Rat7!$D$80 -> 31 | P15: =RawData_Rat7!E76 -> 6 | Q15: =RawData_Rat7!E77 -> 9 | R15: =RawData_Rat7!E79 -> 0 | S15: =RawData_Rat7!E78 -> 11 | T15: =RawData_Rat7!E80 -> 20
B16: R8 | C16: Baseline | D16: 1 | E16: M | K16: =RawData_Rat8!$D$36 -> 1 | L16: =RawData_Rat8!$D$37 -> 6 | M16: =RawData_Rat8!$D$39 -> 2 | N16: =RawData_Rat8!$D$38 -> 25 | O16: =RawData_Rat8!$D$40 -> 31 | P16: =RawData_Rat8!E36 -> 0 | Q16: =RawData_Rat8!E37 -> 2 | R16: =RawData_Rat8!E39 -> 0 | S16: =RawData_Rat8!E38 -> 18 | T16: =RawData_Rat8!E40 -> 20
B17: R8 | C17: Post | D17: 1 | E17: M | K17: =RawData_Rat8!$D$76 -> 2 | L17: =RawData_Rat8!$D$77 -> 4 | M17: =RawData_Rat8!$D$79 -> 0 | N17: =RawData_Rat8!$D$78 -> 24 | O17: =RawData_Rat8!$D$80 -> 28 | P17: =RawData_Rat8!E76 -> 1 | Q17: =RawData_Rat8!E77 -> 2 | R17: =RawData_Rat8!E79 -> 0 | S17: =RawData_Rat8!E78 -> 16 | T17: =RawData_Rat8!E80 -> 18
B18: R9 | C18: Baseline | D18: 2 | E18: F
B19: R9 | C19: Post | D19: 2 | E19: F
B20: R10 | C20: Baseline | D20: 2 | E20: F
B21: R10 | C21: Post | D21: 2 | E21: F
B22: R11 | C22: Baseline | D22: 1 | E22: M | K22: =RawData_Rat11!$D$36 -> 4 | L22: =RawData_Rat11!$D$37 -> 8 | M22: =RawData_Rat11!$D$39 -> 3 | N22: =RawData_Rat11!$D$38 -> 22 | O22: =RawData_Rat11!$D$40 -> 30 | P22: =RawData_Rat11!E36 -> 2 | Q22: =RawData_Rat11!E37 -> 5 | R22: =RawData_Rat11!E39 -> 3 | S22: =RawData_Rat11!E38 -> 15 | T22: =RawData_Rat11!E40 -> 20
B23: R11 | C23: Post | D23: 1 | E23: M | K23: =RawData_Rat11!$D$76 -> 11 | L23: =RawData_Rat11!$D$77 -> 11 | M23: =RawData_Rat11!$D$79 -> 5 | N23: =RawData_Rat11!$D$78 -> 19 | O23: =RawData_Rat11!$D$80 -> 30 | P23: =RawData_Rat11!E76 -> 7 | Q23: =RawData_Rat11!E77 -> 7 | R23: =RawData_Rat11!E79 -> 3 | S23: =RawData_Rat11!E78 -> 13 | T23: =RawData_Rat11!E80 -> 20
B24: R12 | C24: Baseline | D24: 1 | E24: M | K24: =RawData_Rat12!$D$36 -> 0 | L24: =RawData_Rat12!$D$37 -> 3 | M24: =RawData_Rat12!$D$39 -> 1 | N24: =RawData_Rat12!$D$38 -> 24 | O24: =RawData_Rat12!$D$40 -> 27 | P24: =RawData_Rat12!E36 -> 0 | Q24: =RawData_Rat12!E37 -> 1 | R24: =RawData_Rat12!E39 -> 1 | S24: =RawData_Rat12!E38 -> 19 | T24: =RawData_Rat12!E40 -> 20
B25: R12 | C25: Post | D25: 1 | E25: M | K25: =RawData_Rat12!$D$76 -> 2 | L25: =RawData_Rat12!$D$77 -> 2 | M25: =RawData_Rat12!$D$79 -> 15 | N25: =RawData_Rat12!$D$78 -> 28 | O25: =RawData_Rat12!$D$80 -> 30 | P25: =RawData_Rat12!E76 -> 1 | Q25: =RawData_Rat12!E77 -> 1 | R25: =RawData_Rat12!E79 -> 11 | S25: =RawData_Rat12!E78 -> 19 | T25: =RawData_Rat12!E80 -> 20
B26: R13 | C26: Baseline | D26: 1 | E26: F | K26: =RawData_Rat13!$D$36 -> 0 | L26: =RawData_Rat13!$D$37 -> 1 | M26: =RawData_Rat13!$D$39 -> 2 | N26: =RawData_Rat13!$D$38 -> 14 | O26: =RawData_Rat13!$D$40 -> 15 | P26: =RawData_Rat13!E36 -> 0 | Q26: =RawData_Rat13!E37 -> 1 | R26: =RawData_Rat13!E39 -> 2 | S26: =RawData_Rat13!E38 -> 14 | T26: =RawData_Rat13!E40 -> 15
B27: R13 | C27: Post | D27: 1 | E27: F | K27: =RawData_Rat13!$D$76 -> 0 | L27: =RawData_Rat13!$D$77 -> 0 | M27: =RawData_Rat13!$D$79 -> 0 | N27: =RawData_Rat13!$D$78 -> 7 | O27: =RawData_Rat13!$D$80 -> 7 | P27: =RawData_Rat13!E76 -> 0 | Q27: =RawData_Rat13!E77 -> 0 | R27: =RawData_Rat13!E79 -> 0 | S27: =RawData_Rat13!E78 -> 7 | T27: =RawData_Rat13!E80 -> 7
B28: R14 | C28: Baseline | D28: 3 | E28: F | K28: =RawData_Rat14!$D$36 -> 4 | L28: =RawData_Rat14!$D$37 -> 11 | M28: =RawData_Rat14!$D$39 -> 1 | N28: =RawData_Rat14!$D$38 -> 19 | O28: =RawData_Rat14!$D$40 -> 30 | P28: =RawData_Rat14!E36 -> 0 | Q28: =RawData_Rat14!E37 -> 6 | R28: =RawData_Rat14!E39 -> 1 | S28: =RawData_Rat14!E38 -> 14 | T28: =RawData_Rat14!E40 -> 20
B29: R14 | C29: Post | D29: 3 | E29: F | K29: =RawData_Rat14!$D$76 -> 10 | L29: =RawData_Rat14!$D$77 -> 14 | M29: =RawData_Rat14!$D$79 -> 1 | N29: =RawData_Rat14!$D$78 -> 15 | O29: =RawData_Rat14!$D$80 -> 29 | P29: =RawData_Rat14!E76 -> 8 | Q29: =RawData_Rat14!E77 -> 9 | R29: =RawData_Rat14!E79 -> 1 | S29: =RawData_Rat14!E78 -> 11 | T29: =RawData_Rat14!E80 -> 20
B30: R15 | C30: Baseline | D30: 2 | E30: M | K30: =RawData_Rat15!$D$36 -> 3 | L30: =RawData_Rat15!$D$37 -> 4 | M30: =RawData_Rat15!$D$39 -> 8 | N30: =RawData_Rat15!$D$38 -> 26 | O30: =RawData_Rat15!$D$40 -> 30 | P30: =RawData_Rat15!E36 -> 3 | Q30: =RawData_Rat15!E37 -> 4 | R30: =RawData_Rat15!E39 -> 4 | S30: =RawData_Rat15!E38 -> 16 | T30: =RawData_Rat15!E40 -> 20
B31: R15 | C31: Post | D31: 2 | E31: M | K31: =RawData_Rat15!$D$76 -> 0 | L31: =RawData_Rat15!$D$77 -> 0 | M31: =RawData_Rat15!$D$79 -> 0 | N31: =RawData_Rat15!$D$78 -> 0 | O31: =RawData_Rat15!$D$80 -> 0 | P31: =RawData_Rat15!E76 -> 0 | Q31: =RawData_Rat15!E77 -> 0 | R31: =RawData_Rat15!E79 -> 0 | S31: =RawData_Rat15!E78 -> 0 | T31: =RawData_Rat15!E80 -> 0
B32: R16 | C32: Baseline | D32: 1 | E32: M | K32: =RawData_Rat16!$D$36 -> 15 | L32: =RawData_Rat16!$D$37 -> 21 | M32: =RawData_Rat16!$D$39 -> 3 | N32: =RawData_Rat16!$D$38 -> 9 | O32: =RawData_Rat16!$D$40 -> 30 | P32: =RawData_Rat16!E36 -> 11 | Q32: =RawData_Rat16!E37 -> 13 | R32: =RawData_Rat16!E39 -> 2 | S32: =RawData_Rat16!E38 -> 7 | T32: =RawData_Rat16!E40 -> 20
B33: R16 | C33: Post | D33: 1 | E33: M | K33: =RawData_Rat16!$D$76 -> 15 | L33: =RawData_Rat16!$D$77 -> 23 | M33: =RawData_Rat16!$D$79 -> 1 | N33: =RawData_Rat16!$D$78 -> 7 | O33: =RawData_Rat16!$D$80 -> 30 | P33: =RawData_Rat16!E76 -> 9 | Q33: =RawData_Rat16!E77 -> 16 | R33: =RawData_Rat16!E79 -> 1 | S33: =RawData_Rat16!E78 -> 4 | T33: =RawData_Rat16!E80 -> 20
B34: R17 | C34: Baseline | D34: 2 | E34: M | K34: =RawData_Rat17!$D$36 -> 0 | L34: =RawData_Rat17!$D$37 -> 0 | M34: =RawData_Rat17!$D$39 -> 0 | N34: =RawData_Rat17!$D$38 -> 0 | O34: =RawData_Rat17!$D$40 -> 0 | P34: =RawData_Rat17!E36 -> 0 | Q34: =RawData_Rat17!E37 -> 0 | R34: =RawData_Rat17!E39 -> 0 | S34: =RawData_Rat17!E38 -> 0 | T34: =RawData_Rat16!E40 -> 20
B35: R17 | C35: Post | D35: 2 | E35: M | K35: =RawData_Rat17!$D$76 -> 0 | L35: =RawData_Rat17!$D$77 -> 0 | M35: =RawData_Rat17!$D$79 -> 0 | N35: =RawData_Rat17!$D$78 -> 0 | O35: =RawData_Rat17!$D$80 -> 0 | P35: =RawData_Rat17!E76 -> 0 | Q35: =RawData_Rat17!E77 -> 0 | R35: =RawData_Rat17!E79 -> 0 | S35: =RawData_Rat17!E78 -> 0 | T35: =RawData_Rat16!E80 -> 20
B36: R18 | C36: Baseline | D36: 1 | E36: M | K36: =RawData_Rat18!$D$36 -> 2 | L36: =RawData_Rat18!$D$37 -> 4 | M36: =RawData_Rat18!$D$39 -> 1 | N36: =RawData_Rat18!$D$38 -> 27 | O36: =RawData_Rat18!$D$40 -> 31 | P36: =RawData_Rat18!E36 -> 0 | Q36: =RawData_Rat18!E37 -> 0 | R36: =RawData_Rat18!E39 -> 0 | S36: =RawData_Rat18!E38 -> 20 | T36: =RawData_Rat16!E40 -> 20
B37: R18 | C37: Post | D37: 1 | E37: M | K37: =RawData_Rat18!$D$76 -> 1 | L37: =RawData_Rat18!$D$77 -> 1 | M37: =RawData_Rat18!$D$79 -> 0 | N37: =RawData_Rat18!$D$78 -> 27 | O37: =RawData_Rat18!$D$80 -> 28 | P37: =RawData_Rat18!E76 -> 1 | Q37: =RawData_Rat18!E77 -> 1 | R37: =RawData_Rat18!E79 -> 0 | S37: =RawData_Rat18!E78 -> 19 | T37: =RawData_Rat16!E80 -> 20
B38: R19 | C38: Baseline | D38: 2 | E38: F
B39: R19 | C39: Post | D39: 2 | E39: F
B40: R20 | C40: Baseline | D40: 1 | E40: F | K40: =RawData_Rat20!$D$36 -> 11 | L40: =RawData_Rat20!$D$37 -> 15 | M40: =RawData_Rat20!$D$39 -> 0 | N40: =RawData_Rat20!$D$38 -> 15 | O40: =RawData_Rat20!$D$40 -> 30 | P40: =RawData_Rat20!E36 -> 9 | Q40: =RawData_Rat20!E37 -> 12 | R40: =RawData_Rat20!E39 -> 0 | S40: =RawData_Rat20!E38 -> 8 | T40: =RawData_Rat20!E40 -> 20
...

Sheet RawData_Rat1
A2: Number | B2: Animal | C2: Stroke-status | D2: Time stamp | E2: 1st reach - Pellet to Mouth (success) | F2: 1st reach - Pellet to Box (failure) | G2: 2+ reaches - Pellet to Mouth (success) | H2: 2+ reaches - Pellet to Box (failure) | I2: Failure | J2: Dragging (failure)
A3: 1 | B3: Rat 1 | C3: Baseline | D3: 0.0015046296 | E3: 1
A4: 2 | B4: Rat 1 | C4: Baseline | D4: 0.0017476852 | G4: 1
A5: 3 | B5: Rat 1 | C5: Baseline | D5: 0.0018402778 | J5: 1
A6: 4 | B6: Rat 1 | C6: Baseline | D6: 0.0019097222 | J6: 1
A7: 5 | B7: Rat 1 | C7: Baseline | D7: 0.0021296296 | G7: 1
A8: 6 | B8: Rat 1 | C8: Baseline | D8: 0.0022453704 | E8: 1
A9: 7 | B9: Rat 1 | C9: Baseline | D9: 0.0022916667 | G9: 1
A10: 8 | B10: Rat 1 | C10: Baseline | D10: 0.0023726852 | J10: 1
A11: 9 | B11: Rat 1 | C11: Baseline | D11: 0.0025578704 | E11: 1
A12: 10 | B12: Rat 1 | C12: Baseline | D12: 0.002662037 | I12: 1
A13: 11 | B13: Rat 1 | C13: Baseline | D13: 0.0085185185 | E13: 1
A14: 12 | B14: Rat 1 | C14: Baseline | D14: 0.0086342593 | E14: 1
A15: 13 | B15: Rat 1 | C15: Baseline | D15: 0.0087152778 | H15: 1
A16: 14 | B16: Rat 1 | C16: Baseline | D16: 0.0088541667 | J16: 1
A17: 15 | B17: Rat 1 | C17: Baseline | D17: 0.0089236111 | J17: 1
A18: 16 | B18: Rat 1 | C18: Baseline | D18: 0.0090162037 | F18: 1
A19: 17 | B19: Rat 1 | C19: Baseline | D19: 0.0091203704 | I19: 1
A20: 18 | B20: Rat 1 | C20: Baseline | D20: 0.0091898148 | H20: 1
A21: 19 | B21: Rat 1 | C21: Baseline | D21: 0.0092476852 | I21: 1
A22: 20 | B22: Rat 1 | C22: Baseline | D22: 0.0093287037 | G22: 1
A23: 21 | B23: Rat 1 | C23: Baseline | D23: 0.0094212963 | I23: 1
A24: 22 | B24: Rat 1 | C24: Baseline | D24: 0.009537037 | I24: 1
A25: 23 | B25: Rat 1 | C25: Baseline | D25: 0.0096643519 | I25: 1
A26: 24 | B26: Rat 1 | C26: Baseline
A27: 25 | B27: Rat 1 | C27: Baseline
A28: 26 | B28: Rat 1 | C28: Baseline
A29: 27 | B29: Rat 1 | C29: Baseline
A30: 28 | B30: Rat 1 | C30: Baseline
A31: 29 | B31: Rat 1 | C31: Baseline
A32: 30 | B32: Rat 1 | C32: Baseline
A33: 31 | B33: Rat 1 | C33: Baseline
C36: First trial success | D36: =COUNTIF(E3:E33,1) -> 5 | E36: =COUNTIF(E3:E22,1) -> 5
C37: Total success | D37: =COUNTIF(E3:E33,1) + COUNTIF(G3:G33,1) -> 9 | E37: =COUNTIF(E3:E22,1) + COUNTIF(G3:G22,1) -> 9
C38: Total fail | D38: =COUNTIF(F3:F33,1) + COUNTIF(H3:H33,1) + COUNTIF(I3:I33,1) + COUNTIF(J3:J33,1) -> 14 | E38: =COUNTIF(F3:F22,1) + COUNTIF(H3:H22,1) + COUNTIF(I3:I22,1) + COUNTIF(J3:J22,1) -> 11
C39: Total pellet to box | D39: =COUNTIF(F3:F33,1) + COUNTIF(H3:H33,1) -> 3 | E39: =COUNTIF(F3:F22,1) + COUNTIF(H3:H22,1) -> 3
C40: Total grasps | D40: =COUNTIF(F3:F33,1) + COUNTIF(E3:E33,1) + COUNTIF(G3:G33,1) + COUNTIF(H3:H33,1) + COUNTIF(I3:I33,1) + COUNTIF(J3:J33,1) -> 23 | E40: =COUNTIF(E3:E22,1) + COUNTIF(F3:F22,1) + COUNTIF(G3:G22,1) + COUNTIF(H3:H22,1) + COUNTIF(K3:K22,1) + COUNTIF(J3:J22,1) + COUNTIF(I3:I22,1) -> 20
A42: Number | B42: Animal | C42: Stroke-status | D42: Video-number | E42: 1st reach - Pellet to Mouth (success) | F42: 1st reach - Pellet to Box (failure) | G42: 2+ reaches - Pellet to Mouth (success) | H42: 2+ reaches - Pellet to Box (failure) | I42: Failure | J42: Dragging (failure)
A43: 1 | B43: Rat 1 | C43: 3 days post stroke
A44: 2 | B44: Rat 1 | C44: 3 days post stroke
...

Sheet RawData_Rat2
A2: Number | B2: Animal | C2: Stroke-status | D2: Time stamp | E2: 1st reach - Pellet to Mouth (success) | F2: 1st reach - Pellet to Box (failure) | G2: 2+ reaches - Pellet to Mouth (success) | H2: 2+ reaches - Pellet to Box (failure) | I2: Failure | J2: Dragging (failure)
A3: 1 | B3: Rat 2 | C3: Baseline | D3: 0.0009375 | I3: 1
A4: 2 | B4: Rat 2 | C4: Baseline | D4: 0.001412037 | I4: 1
A5: 3 | B5: Rat 2 | C5: Baseline | D5: 0.0022337963 | I5: 1
A6: 4 | B6: Rat 2 | C6: Baseline | D6: 0.0028356481 | I6: 1
A7: 5 | B7: Rat 2 | C7: Baseline | D7: 0.0030324074 | I7: 1
A8: 6 | B8: Rat 2 | C8: Baseline
A9: 7 | B9: Rat 2 | C9: Baseline
A10: 8 | B10: Rat 2 | C10: Baseline
A11: 9 | B11: Rat 2 | C11: Baseline
A12: 10 | B12: Rat 2 | C12: Baseline
A13: 11 | B13: Rat 2 | C13: Baseline
A14: 12 | B14: Rat 2 | C14: Baseline
A15: 13 | B15: Rat 2 | C15: Baseline
A16: 14 | B16: Rat 2 | C16: Baseline
A17: 15 | B17: Rat 2 | C17: Baseline
A18: 16 | B18: Rat 2 | C18: Baseline
A19: 17 | B19: Rat 2 | C19: Baseline
... A33: 31 | B33: Rat 2 | C33: Baseline
C36: First trial success | D36: =COUNTIF(E3:E33,1) -> 0 | E36: =COUNTIF(E3:E22,1) -> 0
C37: Total success | D37: =COUNTIF(E3:E33,1) + COUNTIF(G3:G33,1) -> 0 | E37: =COUNTIF(E3:E22,1) + COUNTIF(G3:G22,1) -> 0
C38: Total fail | D38: =COUNTIF(F3:F33,1) + COUNTIF(H3:H33,1) + COUNTIF(I3:I33,1) + COUNTIF(J3:J33,1) -> 5 | E38: =COUNTIF(F3:F22,1) + COUNTIF(H3:H22,1) + COUNTIF(I3:I22,1) + COUNTIF(J3:J22,1) -> 5
C39: Total pellet to box | D39: =COUNTIF(F3:F33,1) + COUNTIF(H3:H33,1) -> 0 | E39: =COUNTIF(F3:F22,1) + COUNTIF(H3:H22,1) -> 0
C40: Total grasps | D40: =COUNTIF(F3:F33,1) + COUNTIF(E3:E33,1) + COUNTIF(G3:G33,1) + COUNTIF(H3:H33,1) + COUNTIF(I3:I33,1) + COUNTIF(J3:J33,1) -> 5 | E40: =COUNTIF(E3:E22,1) + COUNTIF(F3:F22,1) + COUNTIF(G3:G22,1) + COUNTIF(H3:H22,1) + COUNTIF(K3:K22,1) + COUNTIF(J3:J22,1) + COUNTIF(I3:I22,1) -> 5
A42: Number | B42: Animal | C42: Stroke-status | D42: Video-number | E42: 1st reach - Pellet to Mouth (success) | F42: 1st reach - Pellet to Box (failure) | G42: 2+ reaches - Pellet to Mouth (success) | H42: 2+ reaches - Pellet to Box (failure) | I42: Failure | J42: Dragging (failure)
A43: 1 | B43: Rat 2 | C43: 3 days post stroke
A44: 2 | B44: Rat 2 | C44: 3 days post stroke
A45: 3 | B45: Rat 2 | C45: 3 days post stroke
A46: 4 | B46: Rat 2 | C46: 3 days post stroke
A47: 5 | B47: Rat 2 | C47: 3 days post stroke
A48: 6 | B48: Rat 2 | C48: 3 days post stroke
A49: 7 | B49: Rat 2 | C49: 3 days post stroke
A50: 8 | B50: Rat 2 | C50: 3 days post stroke
A51: 9 | B51: Rat 2 | C51: 3 days post stroke
A52: 10 | B52: Rat 2 | C52: 3 days post stroke
A53: 11 | B53: Rat 2 | C53: 3 days post stroke
A54: 12 | B54: Rat 2 | C54: 3 days post stroke
... A72: 30 | B72: Rat 2 | C72: 3 days post stroke
C76: First trial success | D76: =COUNTIF(E43:E72,1) -> 0 | E76: =COUNTIF(E43:E62,1) -> 0
C77: Total success | D77: =COUNTIF(E43:E72,1) + COUNTIF(G43:G72,1) -> 0 | E77: =COUNTIF(E43:E62,1) + COUNTIF(G43:G62,1) -> 0
...

Sheet RawData_Rat3
A2: Number | B2: Animal | C2: Stroke-status | D2: Video-number | E2: 1st reach - Pellet to Mouth (success) | F2: 1st reach - Pellet to Box (failure) | G2: 2+ reaches - Pellet to Mouth (success) | H2: 2+ reaches - Pellet to Box (failure) | I2: Failure | J2: Dragging (failure)
A3: 1 | B3: Rat 2 | C3: Baseline
A4: 2 | B4: Rat 2 | C4: Baseline
A5: 3 | B5: Rat 2 | C5: Baseline
A6: 4 | B6: Rat 2 | C6: Baseline
A7: 5 | B7: Rat 2 | C7: Baseline
A8: 6 | B8: Rat 2 | C8: Baseline
A9: 7 | B9: Rat 2 | C9: Baseline
A10: 8 | B10: Rat 2 | C10: Baseline
A11: 9 | B11: Rat 2 | C11: Baseline
A12: 10 | B12: Rat 2 | C12: Baseline
A13: 11 | B13: Rat 2 | C13: Baseline
A14: 12 | B14: Rat 2 | C14: Baseline
... A33: 31 | B33: Rat 2 | C33: Baseline
C36: First trial success | D36: =COUNTIF(E3:E33,1) -> 0
C37: Total success | D37: =COUNTIF(E3:E33,1) + COUNTIF(G3:G33,1) -> 0
C38: Total fail | D38: =COUNTIF(F3:F33,1) + COUNTIF(H3:H33,1) + COUNTIF(I3:I33,1) + COUNTIF(J3:J33,1) -> 0
C39: Total pellet to box | D39: =COUNTIF(F3:F33,1) + COUNTIF(H3:H33,1) -> 0
C40: Total grasps | D40: =COUNTIF(F3:F33,1) + COUNTIF(E3:E33,1) + COUNTIF(G3:G33,1) + COUNTIF(H3:H33,1) + COUNTIF(I3:I33,1) + COUNTIF(J3:J33,1) -> 0
A42: Number | B42: Animal | C42: Stroke-status | D42: Video-number | E42: 1st reach - Pellet to Mouth (success) | F42: 1st reach - Pellet to Box (failure) | G42: 2+ reaches - Pellet to Mouth (success) | H42: 2+ reaches - Pellet to Box (failure) | I42: Failure | J42: Dragging (failure)
A43: 1 | B43: Rat 2 | C43: 3 days post stroke
A44: 2 | B44: Rat 2 | C44: 3 days post stroke
A45: 3 | B45: Rat 2 | C45: 3 days post stroke
A46: 4 | B46: Rat 2 | C46: 3 days post stroke
A47: 5 | B47: Rat 2 | C47: 3 days post stroke
A48: 6 | B48: Rat 2 | C48: 3 days post stroke
A49: 7 | B49: Rat 2 | C49: 3 days post stroke
A50: 8 | B50: Rat 2 | C50: 3 days post stroke
A51: 9 | B51: Rat 2 | C51: 3 days post stroke
A52: 10 | B52: Rat 2 | C52: 3 days post stroke
A53: 11 | B53: Rat 2 | C53: 3 days post stroke
A54: 12 | B54: Rat 2 | C54: 3 days post stroke
... A72: 30 | B72: Rat 2 | C72: 3 days post stroke
C76: First trial success | D76: =COUNTIF(E43:E72,1) -> 0
C77: Total success | D77: =COUNTIF(E43:E72,1) + COUNTIF(G43:G72,1) -> 0
C78: Total fail | D78: =COUNTIF(F43:F72,1) + COUNTIF(H43:H72,1) + COUNTIF(I43:I72,1) + COUNTIF(J43:J72,1) -> 0
C79: Total pellet to box | D79: =COUNTIF(F43:F72,1) + COUNTIF(H43:H72,1) -> 0
C80: Total grasps | D80: =COUNTIF(F43:F72,1) + COUNTIF(E43:E72,1) + COUNTIF(G43:G72,1) + COUNTIF(H43:H72,1) + COUNTIF(I43:I72,1) + COUNTIF(J43:J72,1) -> 0

Sheet RawData_Rat4
A2: Number | B2: Animal | C2: Stroke-status | D2: Video-number | E2: 1st reach - Pellet to Mouth (success) | F2: 1st reach - Pellet to Box (failure) | G2: 2+ reaches - Pellet to Mouth (success) | H2: 2+ reaches - Pellet to Box (failure) | I2: Failure | J2: Dragging (failure)
A3: 1 | B3: Rat 4 | C3: Baseline | D3: 100622706 | E3: 1
A4: 2 | B4: Rat 4 | C4: Baseline | D4: 100641376 | G4: 1
A5: 3 | B5: Rat 4 | C5: Baseline | D5: 100706647 | E5: 1
A6: 4 | B6: Rat 4 | C6: Baseline | D6: 100843554 | E6: 1
A7: 5 | B7: Rat 4 | C7: Baseline | D7: 100916605 | I7: 1
A8: 6 | B8: Rat 4 | C8: Baseline | D8: 100937854 | E8: 1
A9: 7 | B9: Rat 4 | C9: Baseline | D9: 100954644 | I9: 1
A10: 8 | B10: Rat 4 | C10: Baseline | D10: 101025548 | E10: 1
A11: 9 | B11: Rat 4 | C11: Baseline | D11: 101109273 | I11: 1
A12: 10 | B12: Rat 4 | C12: Baseline | D12: 101130698 | I12: 1
A13: 11 | B13: Rat 4 | C13: Baseline | D13: 101147484 | I13: 1
A14: 12 | B14: Rat 4 | C14: Baseline | D14: 101218873 | E14: 1
A15: 13 | B15: Rat 4 | C15: Baseline | D15: 101229281 | E15: 1
A16: 14 | B16: Rat 4 | C16: Baseline | D16: 101242188 | G16: 1
A17: 15 | B17: Rat 4 | C17: Baseline | D17: 101256983 | E17: 1
A18: 16 | B18: Rat 4 | C18: Baseline | D18: 101322191 | G18: 1
A19: 17 | B19: Rat 4 | C19: Baseline | D19: 101334691 | G19: 1
A20: 18 | B20: Rat 4 | C20: Baseline | D20: 101346337 | E20: 1
A21: 19 | B21: Rat 4 | C21: Baseline | D21: 101408495 | E21: 1
A22: 20 | B22: Rat 4 | C22: Baseline | D22: 101420748 | E22: 1
A23: 21 | B23: Rat 4 | C23: Baseline | D23: 101438487 | E23: 1
A24: 22 | B24: Rat 4 | C24: Baseline | D24: 101459957 | E24: 1
A25: 23 | B25: Rat 4 | C25: Baseline | D25: 101520544 | I25: 1
A26: 24 | B26: Rat 4 | C26: Baseline | D26: 101535354 | E26: 1
A27: 25 | B27: Rat 4 | C27: Baseline | D27: 101547939 | E27: 1
A28: 26 | B28: Rat 4 | C28: Baseline | D28: 101556441 | E28: 1
A29: 27 | B29: Rat 4 | C29: Baseline | D29: 101613510 | E29: 1
A30: 28 | B30: Rat 4 | C30: Baseline | D30: 101640313 | G30: 1
A31: 29 | B31: Rat 4 | C31: Baseline | D31: 101726610 | I31: 1
A32: 30 | B32: Rat 4 | C32: Baseline | D32: 101740712 | E32: 1
A33: 31 | B33: Rat 4 | C33: Baseline | D33: 101801233 | E33: 1
C36: First trial success | D36: =COUNTIF(E3:E33,1) -> 19 | E36: =COUNTIF(E3:E22,1) -> 11
C37: Total success | D37: =COUNTIF(E3:E33,1) + COUNTIF(G3:G33,1) -> 24 | E37: =COUNTIF(E3:E22,1) + COUNTIF(G3:G22,1) -> 15
C38: Total fail | D38: =COUNTIF(F3:F33,1) + COUNTIF(H3:H33,1) + COUNTIF(I3:I33,1) + COUNTIF(J3:J33,1) -> 7 | E38: =COUNTIF(F3:F22,1) + COUNTIF(H3:H22,1) + COUNTIF(I3:I22,1) + COUNTIF(J3:J22,1) -> 5
C39: Total pellet to box | D39: =COUNTIF(F3:F33,1) + COUNTIF(H3:H33,1) -> 0 | E39: =COUNTIF(F3:F22,1) + COUNTIF(H3:H22,1) -> 0
C40: Total grasps | D40: =COUNTIF(F3:F33,1) + COUNTIF(E3:E33,1) + COUNTIF(G3:G33,1) + COUNTIF(H3:H33,1) + COUNTIF(I3:I33,1) + COUNTIF(J3:J33,1) -> 31 | E40: =COUNTIF(E3:E22,1) + COUNTIF(F3:F22,1) + COUNTIF(G3:G22,1) + COUNTIF(H3:H22,1) + COUNTIF(K3:K22,1) + COUNTIF(J3:J22,1) + COUNTIF(I3:I22,1) -> 20
A42: Number | B42: Animal | C42: Stroke-status | D42: Video-number | E42: 1st reach - Pellet to Mouth (success) | F42: 1st reach - Pellet to Box (failure) | G42: 2+ reaches - Pellet to Mouth (success) | H42: 2+ reaches - Pellet to Box (failure) | I42: Failure | J42: Dragging (failure)
A43: 1 | B43: Rat 4 | C43: 3 days post stroke | D43: 100027139 | F43: 1
A44: 2 | B44: Rat 4 | C44: 3 days post stroke | D44: 100050615 | I44: 1
...

Sheet RawData_Rat5
A2: Number | B2: Animal | C2: Stroke-status | D2: Video-number | E2: 1st reach - Pellet to Mouth (success) | F2: 1st reach - Pellet to Box (failure) | G2: 2+ reaches - Pellet to Mouth (success) | H2: 2+ reaches - Pellet to Box (failure) | I2: Failure | J2: Dragging (failure)
A3: 1 | B3: Rat 5 | C3: Baseline | D3: Basler_acA720-520uc__40502463__20250312_095049315 | I3: 1
A4: 2 | B4: Rat 5 | C4: Baseline | D4: Basler_acA720-520uc__40502463__20250312_095111453 | H4: 1
A5: 3 | B5: Rat 5 | C5: Baseline | D5: Basler_acA720-520uc__40502463__20250312_095137718 | I5: 1
A6: 4 | B6: Rat 5 | C6: Baseline | D6: Basler_acA720-520uc__40502463__20250312_095205302 | I6: 1
A7: 5 | B7: Rat 5 | C7: Baseline | D7: Basler_acA720-520uc__40502463__20250312_095236667 | I7: 1
A8: 6 | B8: Rat 5 | C8: Baseline | D8: Basler_acA720-520uc__40502463__20250312_095338802 | E8: 1
A9: 7 | B9: Rat 5 | C9: Baseline | D9: Basler_acA720-520uc__40502463__20250312_095350151
A10: 8 | B10: Rat 5 | C10: Baseline | D10: Basler_acA720-520uc__40502463__20250312_095409145 | I10: 1
A11: 9 | B11: Rat 5 | C11: Baseline | D11: Basler_acA720-520uc__40502463__20250312_095444939 | I11: 1
A12: 10 | B12: Rat 5 | C12: Baseline | D12: Basler_acA720-520uc__40502463__20250312_095504659 | I12: 1
A13: 11 | B13: Rat 5 | C13: Baseline | D13: Basler_acA720-520uc__40502463__20250312_095533028 | I13: 1
A14: 12 | B14: Rat 5 | C14: Baseline | D14: Basler_acA720-520uc__40502463__20250312_095558582 | E14: 1
A15: 13 | B15: Rat 5 | C15: Baseline | D15: Basler_acA720-520uc__40502463__20250312_095617876 | I15: 1
A16: 14 | B16: Rat 5 | C16: Baseline | D16: Basler_acA720-520uc__40502463__20250312_095704979 | G16: 1
A17: 15 | B17: Rat 5 | C17: Baseline | D17: Basler_acA720-520uc__40502463__20250312_095720954 | I17: 1
A18: 16 | B18: Rat 5 | C18: Baseline | D18: Basler_acA720-520uc__40502463__20250312_095747271 | I18: 1
A19: 17 | B19: Rat 5 | C19: Baseline | D19: Basler_acA720-520uc__40502463__20250312_095812175 | I19: 1
A20: 18 | B20: Rat 5 | C20: Baseline | D20: Basler_acA720-520uc__40502463__20250312_095850086 | I20: 1
A21: 19 | B21: Rat 5 | C21: Baseline | D21: Basler_acA720-520uc__40502463__20250312_095922953 | I21: 1
A22: 20 | B22: Rat 5 | C22: Baseline | D22: Basler_acA720-520uc__40502463__20250312_100014682 | G22: 1
A23: 21 | B23: Rat 5 | C23: Baseline | D23: Basler_acA720-520uc__40502463__20250312_100038395 | I23: 1
A24: 22 | B24: Rat 5 | C24: Baseline | D24: Basler_acA720-520uc__40502463__20250312_100053442 | I24: 1
A25: 23 | B25: Rat 5 | C25: Baseline | D25: Basler_acA720-520uc__40502463__20250312_100227319 | I25: 1
A26: 24 | B26: Rat 5 | C26: Baseline | D26: Basler_acA720-520uc__40502463__20250312_100334846 | I26: 1
A27: 25 | B27: Rat 5 | C27: Baseline | D27: Basler_acA720-520uc__40502463__20250312_100411284 | E27: 1
A28: 26 | B28: Rat 5 | C28: Baseline | D28: Basler_acA720-520uc__40502463__20250312_100508072 | E28: 1
A29: 27 | B29: Rat 5 | C29: Baseline | D29: Basler_acA720-520uc__40502463__20250312_100545970 | I29: 1
A30: 28 | B30: Rat 5 | C30: Baseline | D30: Basler_acA720-520uc__40502463__20250312_100604511 | I30: 1
A31: 29 | B31: Rat 5 | C31: Baseline
A32: 30 | B32: Rat 5 | C32: Baseline
C35: First trial success | D35: =COUNTIF(E3:E32,1) -> 4 | E35: =COUNTIF(E2:E21,1) -> 2
C36: Total success | D36: =COUNTIF(E3:E32,1) + COUNTIF(G3:G32,1) -> 6 | E36: =COUNTIF(E2:E21,1) + COUNTIF(G2:G21,1) -> 3
C37: Total fail | D37: =COUNTIF(F3:F32,1) + COUNTIF(H3:H32,1) + COUNTIF(I3:I32,1) + COUNTIF(J3:J32,1) -> 21 | E37: =COUNTIF(F2:F21,1) + COUNTIF(H2:H21,1) + COUNTIF(I2:I21,1) + COUNTIF(J2:J21,1) -> 15
C38: Total pellet to box | D38: =COUNTIF(F3:F32,1) + COUNTIF(H3:H32,1) -> 1 | E38: =COUNTIF(F2:F21,1) + COUNTIF(H2:H21,1) -> 1
C39: Total grasps | D39: =COUNTIF(F3:F32,1) + COUNTIF(E3:E32,1) + COUNTIF(G3:G32,1) + COUNTIF(H3:H32,1) + COUNTIF(I3:I32,1) + COUNTIF(J3:J32,1) -> 27 | E39: =COUNTIF(E2:E21,1) + COUNTIF(F2:F21,1) + COUNTIF(G2:G21,1) + COUNTIF(H2:H21,1) + COUNTIF(K2:K21,1) + COUNTIF(J2:J21,1) + COUNTIF(I2:I21,1) -> 18
A42: Number | B42: Animal | C42: Stroke-status | D42: Video-number | E42: 1st reach - Pellet to Mouth (success) | F42: 1st reach - Pellet to Box (failure) | G42: 2+ reaches - Pellet to Mouth (success) | H42: 2+ reaches - Pellet to Box (failure) | I42: Failure | J42: Dragging (failure)
A43: 1 | B43: Rat 5 | C43: 3 days post stroke | D43: Basler_acA720-520uc__40502463__20250320_100445762 | I43: 1
A44: 2 | B44: Rat 5 | C44: 3 days post stroke | D44: Basler_acA720-520uc__40502463__20250320_100619002 | I44: 1
A45: 3 | B45: Rat 5 | C45: 3 days post stroke | D45: Basler_acA720-520uc__40502463__20250320_100903112
...

Sheet RawData_Rat6
A2: Number | B2: Animal | C2: Stroke-status | D2: Video-number | E2: 1st reach - Pellet to Mouth (success) | F2: 1st reach - Pellet to Box (failure) | G2: 2+ reaches - Pellet to Mouth (success) | H2: 2+ reaches - Pellet to Box (failure) | I2: Failure | J2: Dragging (failure)
A3: 1 | B3: Rat 6 | C3: Baseline | D3: Basler_acA720-520uc__40502463__20250321_112647342 | G3: 1
A4: 2 | B4: Rat 6 | C4: Baseline | D4: Basler_acA720-520uc__40502463__20250321_112702094 | J4: 1
A5: 3 | B5: Rat 6 | C5: Baseline | D5: Basler_acA720-520uc__40502463__20250321_112720933 | I5: 1
A6: 4 | B6: Rat 6 | C6: Baseline | D6: Basler_acA720-520uc__40502463__20250321_112748221 | I6: 1
A7: 5 | B7: Rat 6 | C7: Baseline | D7: Basler_acA720-520uc__40502463__20250321_112831095 | I7: 1
A8: 6 | B8: Rat 6 | C8: Baseline | D8: Basler_acA720-520uc__40502463__20250321_112904940 | I8: 1
A9: 7 | B9: Rat 6 | C9: Baseline | D9: Basler_acA720-520uc__40502463__20250321_112927083 | J9: 1
A10: 8 | B10: Rat 6 | C10: Baseline | D10: Basler_acA720-520uc__40502463__20250321_113006128 | J10: 1
A11: 9 | B11: Rat 6 | C11: Baseline | D11: Basler_acA720-520uc__40502463__20250321_113018228 | I11: 1
A12: 10 | B12: Rat 6 | C12: Baseline | D12: Basler_acA720-520uc__40502463__20250321_113103999 | J12: 1
A13: 11 | B13: Rat 6 | C13: Baseline | D13: Basler_acA720-520uc__40502463__20250321_113126887 | F13: 1
A14: 12 | B14: Rat 6 | C14: Baseline | D14: Basler_acA720-520uc__40502463__20250321_113147221 | J14: 1
A15: 13 | B15: Rat 6 | C15: Baseline | D15: Basler_acA720-520uc__40502463__20250321_113253251 | E15: 1
A16: 14 | B16: Rat 6 | C16: Baseline | D16: Basler_acA720-520uc__40502463__20250321_113303858 | F16: 1
A17: 15 | B17: Rat 6 | C17: Baseline | D17: Basler_acA720-520uc__40502463__20250321_113325516 | G17: 1
A18: 16 | B18: Rat 6 | C18: Baseline | D18: Basler_acA720-520uc__40502463__20250321_113401306 | J18: 1
A19: 17 | B19: Rat 6 | C19: Baseline | D19: Basler_acA720-520uc__40502463__20250321_113455327 | E19: 1
A20: 18 | B20: Rat 6 | C20: Baseline | D20: Basler_acA720-520uc__40502463__20250321_113523701 | J20: 1
A21: 19 | B21: Rat 6 | C21: Baseline | D21: Basler_acA720-520uc__40502463__20250321_113542058 | J21: 1
A22: 20 | B22: Rat 6 | C22: Baseline | D22: Basler_acA720-520uc__40502463__20250321_113900931 | J22: 1
A23: 21 | B23: Rat 6 | C23: Baseline | D23: Basler_acA720-520uc__40502463__20250321_113925216 | J23: 1
A24: 22 | B24: Rat 6 | C24: Baseline | D24: Basler_acA720-520uc__40502463__20250321_113947801 | E24: 1
A25: 23 | B25: Rat 6 | C25: Baseline | D25: Basler_acA720-520uc__40502463__20250321_114009418 | J25: 1
A26: 24 | B26: Rat 6 | C26: Baseline | D26: Basler_acA720-520uc__40502463__20250321_114036697 | G26: 1
A27: 25 | B27: Rat 6 | C27: Baseline | D27: Basler_acA720-520uc__40502463__20250321_114103646 | F27: 1
A28: 26 | B28: Rat 6 | C28: Baseline | D28: Basler_acA720-520uc__40502463__20250321_114120041 | I28: 1
A29: 27 | B29: Rat 6 | C29: Baseline | D29: Basler_acA720-520uc__40502463__20250321_114200800 | J29: 1
A30: 28 | B30: Rat 6 | C30: Baseline | D30: Basler_acA720-520uc__40502463__20250321_114225070 | E30: 1
A31: 29 | B31: Rat 6 | C31: Baseline | D31: Basler_acA720-520uc__40502463__20250321_114241884 | I31: 1
A32: 30 | B32: Rat 6 | C32: Baseline
A33: 31 | B33: Rat 6 | C33: Baseline
C36: First trial success | D36: =COUNTIF(E3:E33,1) -> 4 | E36: =COUNTIF(E3:E22,1) -> 2
C37: Total success | D37: =COUNTIF(E3:E33,1) + COUNTIF(G3:G33,1) -> 7 | E37: =COUNTIF(E3:E22,1) + COUNTIF(G3:G22,1) -> 4
C38: Total fail | D38: =COUNTIF(F3:F33,1) + COUNTIF(H3:H33,1) + COUNTIF(I3:I33,1) + COUNTIF(J3:J33,1) -> 22 | E38: =COUNTIF(F3:F22,1) + COUNTIF(H3:H22,1) + COUNTIF(I3:I22,1) + COUNTIF(J3:J22,1) -> 16
C39: Total pellet to box | D39: =COUNTIF(F3:F33,1) + COUNTIF(H3:H33,1) -> 3 | E39: =COUNTIF(F3:F22,1) + COUNTIF(H3:H22,1) -> 2
C40: Total grasps | D40: =COUNTIF(E3:E33,1) + COUNTIF(F3:F33,1) + COUNTIF(G3:G33,1) + COUNTIF(H3:H33,1) +COUNTIF(I3:I33,1) + COUNTIF(J3:J33,1) -> 29 | E40: =COUNTIF(E3:E22,1) + COUNTIF(F3:F22,1) + COUNTIF(G3:G22,1) + COUNTIF(H3:H22,1) + COUNTIF(K3:K22,1) + COUNTIF(J3:J22,1) + COUNTIF(I3:I22,1) -> 20
A42: Number | B42: Animal | C42: Stroke-status | D42: Video-number | E42: 1st reach - Pellet to Mouth (success) | F42: 1st reach - Pellet to Box (failure) | G42: 2+ reaches - Pellet to Mouth (success) | H42: 2+ reaches - Pellet to Box (failure) | I42: Failure | J42: Dragging (failure)
A43: 1 | B43: Rat 6 | C43: 3 days post stroke | D43: Basler_acA720-520uc__40502463__20250327_095926661 | I43: 1
A44: 2 | B44: Rat 6 | C44: 3 days post stroke | D44: Basler_acA720-520uc__40502463__20250327_100012178 | I44: 1
...

Sheet RawData_Rat7
A2: Number | B2: Animal | C2: Stroke-status | D2: Video-number | E2: 1st reach - Pellet to Mouth (success) | F2: 1st reach - Pellet to Box (failure) | G2: 2+ reaches - Pellet to Mouth (success) | H2: 2+ reaches - Pellet to Box (failure) | I2: Failure | J2: Dragging (failure)
A3: 1 | B3: Rat 7 | C3: Baseline | D3: Basler_acA720-520uc__40502463__20250326_101200711 | I3: 1
A4: 2 | B4: Rat 7 | C4: Baseline | D4: Basler_acA720-520uc__40502463__20250326_101341207 | E4: 1
A5: 3 | B5: Rat 7 | C5: Baseline | D5: Basler_acA720-520uc__40502463__20250326_101409322 | I5: 1
A6: 4 | B6: Rat 7 | C6: Baseline | D6: Basler_acA720-520uc__40502463__20250326_101512144 | I6: 1
A7: 5 | B7: Rat 7 | C7: Baseline | D7: Basler_acA720-520uc__40502463__20250326_101531246 | I7: 1
A8: 6 | B8: Rat 7 | C8: Baseline | D8: Basler_acA720-520uc__40502463__20250326_101556936 | I8: 1
A9: 7 | B9: Rat 7 | C9: Baseline | D9: Basler_acA720-520uc__40502463__20250326_101643693 | I9: 1
A10: 8 | B10: Rat 7 | C10: Baseline | D10: Basler_acA720-520uc__40502463__20250326_101734887 | I10: 1
A11: 9 | B11: Rat 7 | C11: Baseline | D11: Basler_acA720-520uc__40502463__20250326_101818626 | I11: 1
A12: 10 | B12: Rat 7 | C12: Baseline | D12: Basler_acA720-520uc__40502463__20250326_101837384 | I12: 1
A13: 11 | B13: Rat 7 | C13: Baseline | D13: Basler_acA720-520uc__40502463__20250326_101856851 | I13: 1
A14: 12 | B14: Rat 7 | C14: Baseline | D14: Basler_acA720-520uc__40502463__20250326_101930313 | I14: 1
A15: 13 | B15: Rat 7 | C15: Baseline | D15: Basler_acA720-520uc__40502463__20250326_102003022 | I15: 1
A16: 14 | B16: Rat 7 | C16: Baseline | D16: Basler_acA720-520uc__40502463__20250326_102037409 | I16: 1
A17: 15 | B17: Rat 7 | C17: Baseline | D17: Basler_acA720-520uc__40502463__20250326_102115646 | I17: 1
A18: 16 | B18: Rat 7 | C18: Baseline | D18: Basler_acA720-520uc__40502463__20250326_102206179 | E18: 1
A19: 17 | B19: Rat 7 | C19: Baseline | D19: Basler_acA720-520uc__40502463__20250326_102227762 | I19: 1
A20: 18 | B20: Rat 7 | C20: Baseline | D20: Basler_acA720-520uc__40502463__20250326_102238767 | I20: 1
A21: 19 | B21: Rat 7 | C21: Baseline | D21: Basler_acA720-520uc__40502463__20250326_102306644 | I21: 1
A22: 20 | B22: Rat 7 | C22: Baseline | D22: Basler_acA720-520uc__40502463__20250326_102344644 | I22: 1
A23: 21 | B23: Rat 7 | C23: Baseline | D23: Basler_acA720-520uc__40502463__20250326_102413691 | G23: 1
A24: 22 | B24: Rat 7 | C24: Baseline | D24: Basler_acA720-520uc__40502463__20250326_102455507 | G24: 1
A25: 23 | B25: Rat 7 | C25: Baseline | D25: Basler_acA720-520uc__40502463__20250326_102551473 | I25: 1
A26: 24 | B26: Rat 7 | C26: Baseline | D26: Basler_acA720-520uc__40502463__20250326_102632367 | E26: 1
A27: 25 | B27: Rat 7 | C27: Baseline | D27: Basler_acA720-520uc__40502463__20250326_102737711 | E27: 1
A28: 26 | B28: Rat 7 | C28: Baseline | D28: Basler_acA720-520uc__40502463__20250326_102805772 | I28: 1
A29: 27 | B29: Rat 7 | C29: Baseline | D29: Basler_acA720-520uc__40502463__20250326_102831301 | I29: 1
A30: 28 | B30: Rat 7 | C30: Baseline | D30: Basler_acA720-520uc__40502463__20250326_102902765 | I30: 1
A31: 29 | B31: Rat 7 | C31: Baseline | D31: Basler_acA720-520uc__40502463__20250326_102915158 | I31: 1
A32: 30 | B32: Rat 7 | C32: Baseline | D32: Basler_acA720-520uc__40502463__20250326_102943015 | I32: 1
A33: 31 | B33: Rat 7 | C33: Baseline | D33: Basler_acA720-520uc__40502463__20250326_103013281 | I33: 1
C36: First trial success | D36: =COUNTIF(E3:E33,1) -> 4 | E36: =COUNTIF(E3:E22,1) -> 2
C37: Total success | D37: =COUNTIF(E3:E33,1) + COUNTIF(G3:G33,1) -> 6 | E37: =COUNTIF(E3:E22,1) + COUNTIF(G3:G22,1) -> 2
C38: Total fail | D38: =COUNTIF(F3:F33,1) + COUNTIF(H3:H33,1) + COUNTIF(I3:I33,1) + COUNTIF(J3:J33,1) -> 25 | E38: =COUNTIF(F3:F22,1) + COUNTIF(H3:H22,1) + COUNTIF(I3:I22,1) + COUNTIF(J3:J22,1) -> 18
C39: Total pellet to box | D39: =COUNTIF(F3:F33,1) + COUNTIF(H3:H33,1) -> 0 | E39: =COUNTIF(F3:F22,1) + COUNTIF(H3:H22,1) -> 0
C40: Total grasps | D40: =COUNTIF(E3:E33,1) + COUNTIF(F3:F33,1) + COUNTIF(G3:G33,1) + COUNTIF(H3:H33,1) +COUNTIF(I3:I33,1) + COUNTIF(J3:J33,1) -> 31 | E40: =COUNTIF(E3:E22,1) + COUNTIF(F3:F22,1) + COUNTIF(G3:G22,1) + COUNTIF(H3:H22,1) + COUNTIF(K3:K22,1) + COUNTIF(J3:J22,1) + COUNTIF(I3:I22,1) -> 20
A42: Number | B42: Animal | C42: Stroke-status | D42: Video-number | E42: 1st reach - Pellet to Mouth (success) | F42: 1st reach - Pellet to Box (failure) | G42: 2+ reaches - Pellet to Mouth (success) | H42: 2+ reaches - Pellet to Box (failure) | I42: Failure | J42: Dragging (failure)
A43: 1 | B43: Rat 7 | C43: 3 days post stroke | D43: Basler_acA720-520uc__40502463__20250403_101727274 | I43: 1
A44: 2 | B44: Rat 7 | C44: 3 days post stroke | D44: Basler_acA720-520uc__40502463__20250403_101746256 | E44: 1
...

Sheet RawData_Rat8
A2: Number | B2: Animal | C2: Stroke-status | D2: Video-number | E2: 1st reach - Pellet to Mouth (success) | F2: 1st reach - Pellet to Box (failure) | G2: 2+ reaches - Pellet to Mouth (success) | H2: 2+ reaches - Pellet to Box (failure) | I2: Failure | J2: Dragging (failure)
A3: 1 | B3: Rat 8 | C3: Baseline | D3: Basler_acA720-520uc__40502463__20250401_101726260 | I3: 1
A4: 2 | B4: Rat 8 | C4: Baseline | D4: Basler_acA720-520uc__40502463__20250401_101752401 | I4: 1
A5: 3 | B5: Rat 8 | C5: Baseline | D5: Basler_acA720-520uc__40502463__20250401_101820941 | I5: 1
A6: 4 | B6: Rat 8 | C6: Baseline | D6: Basler_acA720-520uc__40502463__20250401_101851753 | I6: 1
A7: 5 | B7: Rat 8 | C7: Baseline | D7: Basler_acA720-520uc__40502463__20250401_101917960 | G7: 1
A8: 6 | B8: Rat 8 | C8: Baseline | D8: Basler_acA720-520uc__40502463__20250401_102105077 | I8: 1
A9: 7 | B9: Rat 8 | C9: Baseline | D9: Basler_acA720-520uc__40502463__20250401_102133479 | I9: 1
A10: 8 | B10: Rat 8 | C10: Baseline | D10: Basler_acA720-520uc__40502463__20250401_102220551 | I10: 1
A11: 9 | B11: Rat 8 | C11: Baseline | D11: Basler_acA720-520uc__40502463__20250401_102302242 | I11: 1
A12: 10 | B12: Rat 8 | C12: Baseline | D12: Basler_acA720-520uc__40502463__20250401_102327292 | I12: 1
A13: 11 | B13: Rat 8 | C13: Baseline | D13: Basler_acA720-520uc__40502463__20250401_102653290 | I13: 1
A14: 12 | B14: Rat 8 | C14: Baseline | D14: Basler_acA720-520uc__40502463__20250401_102808916 | I14: 1
A15: 13 | B15: Rat 8 | C15: Baseline | D15: Basler_acA720-520uc__40502463__20250401_102848716 | I15: 1
A16: 14 | B16: Rat 8 | C16: Baseline | D16: Basler_acA720-520uc__40502463__20250401_102956210 | I16: 1
A17: 15 | B17: Rat 8 | C17: Baseline | D17: Basler_acA720-520uc__40502463__20250401_103059367 | I17: 1
A18: 16 | B18: Rat 8 | C18: Baseline | D18: Basler_acA720-520uc__40502463__20250401_103224843 | I18: 1
A19: 17 | B19: Rat 8 | C19: Baseline | D19: Basler_acA720-520uc__40502463__20250401_103457449 | I19: 1
A20: 18 | B20: Rat 8 | C20: Baseline | D20: Basler_acA720-520uc__40502463__20250401_103624504 | I20: 1
A21: 19 | B21: Rat 8 | C21: Baseline | D21: Basler_acA720-520uc__40502463__20250401_103717537 | G21: 1
A22: 20 | B22: Rat 8 | C22: Baseline | D22: Basler_acA720-520uc__40502463__20250401_103741098 | I22: 1
A23: 21 | B23: Rat 8 | C23: Baseline | D23: Basler_acA720-520uc__40502463__20250401_103824501 | I23: 1
A24: 22 | B24: Rat 8 | C24: Baseline | D24: Basler_acA720-520uc__40502463__20250401_103942041 | G24: 1
A25: 23 | B25: Rat 8 | C25: Baseline | D25: Basler_acA720-520uc__40502463__20250401_104021691 | I25: 1
A26: 24 | B26: Rat 8 | C26: Baseline | D26: Basler_acA720-520uc__40502463__20250401_104056225 | E26: 1
A27: 25 | B27: Rat 8 | C27: Baseline | D27: Basler_acA720-520uc__40502463__20250401_104145421 | I27: 1
A28: 26 | B28: Rat 8 | C28: Baseline | D28: Basler_acA720-520uc__40502463__20250401_104243854 | G28: 1
A29: 27 | B29: Rat 8 | C29: Baseline | D29: Basler_acA720-520uc__40502463__20250401_104412132 | I29: 1
A30: 28 | B30: Rat 8 | C30: Baseline | D30: Basler_acA720-520uc__40502463__20250401_104441793 | H30: 1
A31: 29 | B31: Rat 8 | C31: Baseline | D31: Basler_acA720-520uc__40502463__20250401_104511218 | I31: 1
A32: 30 | B32: Rat 8 | C32: Baseline | D32: Basler_acA720-520uc__40502463__20250401_104558140 | G32: 1
A33: 31 | B33: Rat 8 | C33: Baseline | D33: Basler_acA720-520uc__40502463__20250401_104636404 | H33: 1
C36: First trial success | D36: =COUNTIF(E3:E33,1) -> 1 | E36: =COUNTIF(E3:E22,1) -> 0
C37: Total success | D37: =COUNTIF(E3:E33,1) + COUNTIF(G3:G33,1) -> 6 | E37: =COUNTIF(E3:E22,1) + COUNTIF(G3:G22,1) -> 2
C38: Total fail | D38: =COUNTIF(F3:F33,1) + COUNTIF(H3:H33,1) + COUNTIF(I3:I33,1) + COUNTIF(J3:J33,1) -> 25 | E38: =COUNTIF(F3:F22,1) + COUNTIF(H3:H22,1) + COUNTIF(I3:I22,1) + COUNTIF(J3:J22,1) -> 18
C39: Total pellet to box | D39: =COUNTIF(F3:F33,1) + COUNTIF(H3:H33,1) -> 2 | E39: =COUNTIF(F3:F22,1) + COUNTIF(H3:H22,1) -> 0
C40: Total grasps | D40: =COUNTIF(F3:F33,1) + COUNTIF(E3:E33,1) + COUNTIF(G3:G33,1) + COUNTIF(H3:H33,1) + COUNTIF(I3:I33,1) + COUNTIF(J3:J33,1) -> 31 | E40: =COUNTIF(E3:E22,1) + COUNTIF(F3:F22,1) + COUNTIF(G3:G22,1) + COUNTIF(H3:H22,1) + COUNTIF(K3:K22,1) + COUNTIF(J3:J22,1) + COUNTIF(I3:I22,1) -> 20
A42: Number | B42: Animal | C42: Stroke-status | D42: Video-number | E42: 1st reach - Pellet to Mouth (success) | F42: 1st reach - Pellet to Box (failure) | G42: 2+ reaches - Pellet to Mouth (success) | H42: 2+ reaches - Pellet to Box (failure) | I42: Failure | J42: Dragging (failure)
A43: 1 | B43: Rat 8 | C43: 3 days post stroke | D43: Basler_acA720-520uc__40502463__20250410_093803509 | I43: 1
A44: 2 | B44: Rat 8 | C44: 3 days post stroke | D44: Basler_acA720-520uc__40502463__20250410_093845047 | I44: 1
...

Sheet RawData_Rat9
A2: Number | B2: Animal | C2: Stroke-status | D2: Video-number | E2: 1st reach - Pellet to Mouth (success) | F2: 1st reach - Pellet to Box (failure) | G2: 2+ reaches - Pellet to Mouth (success) | H2: 2+ reaches - Pellet to Box (failure) | I2: Failure | J2: Dragging (failure)
A3: 1 | B3: Rat 9 | C3: Baseline
A4: 2 | B4: Rat 9 | C4: Baseline
A5: 3 | B5: Rat 9 | C5: Baseline
A6: 4 | B6: Rat 9 | C6: Baseline
A7: 5 | B7: Rat 9 | C7: Baseline
A8: 6 | B8: Rat 9 | C8: Baseline
A9: 7 | B9: Rat 9 | C9: Baseline
A10: 8 | B10: Rat 9 | C10: Baseline
A11: 9 | B11: Rat 9 | C11: Baseline
A12: 10 | B12: Rat 9 | C12: Baseline
A13: 11 | B13: Rat 9 | C13: Baseline
A14: 12 | B14: Rat 9 | C14: Baseline
... A33: 31 | B33: Rat 9 | C33: Baseline
C36: First trial success | D36: =COUNTIF(E3:E33,1) -> 0
C37: Total success | D37: =COUNTIF(E3:E33,1) + COUNTIF(G3:G33,1) -> 0
C38: Total fail | D38: =COUNTIF(F3:F33,1) + COUNTIF(H3:H33,1) + COUNTIF(I3:I33,1) + COUNTIF(J3:J33,1) -> 0
C39: Total pellet to box | D39: =COUNTIF(F3:F33,1) + COUNTIF(H3:H33,1) -> 0
C40: Total grasps | D40: =COUNTIF(F3:F33,1) + COUNTIF(E3:E33,1) + COUNTIF(G3:G33,1) + COUNTIF(H3:H33,1) + COUNTIF(I3:I33,1) + COUNTIF(J3:J33,1) -> 0
A42: Number | B42: Animal | C42: Stroke-status | D42: Video-number | E42: 1st reach - Pellet to Mouth (success) | F42: 1st reach - Pellet to Box (failure) | G42: 2+ reaches - Pellet to Mouth (success) | H42: 2+ reaches - Pellet to Box (failure) | I42: Failure | J42: Dragging (failure)
A43: 1 | B43: Rat 9 | C43: 3 days post stroke
A44: 2 | B44: Rat 9 | C44: 3 days post stroke
A45: 3 | B45: Rat 9 | C45: 3 days post stroke
A46: 4 | B46: Rat 9 | C46: 3 days post stroke
A47: 5 | B47: Rat 9 | C47: 3 days post stroke
A48: 6 | B48: Rat 9 | C48: 3 days post stroke
A49: 7 | B49: Rat 9 | C49: 3 days post stroke
A50: 8 | B50: Rat 9 | C50: 3 days post stroke
A51: 9 | B51: Rat 9 | C51: 3 days post stroke
A52: 10 | B52: Rat 9 | C52: 3 days post stroke
A53: 11 | B53: Rat 9 | C53: 3 days post stroke
A54: 12 | B54: Rat 9 | C54: 3 days post stroke
... A72: 30 | B72: Rat 9 | C72: 3 days post stroke
C76: First trial success | D76: =COUNTIF(E43:E72,1) -> 0
C77: Total success | D77: =COUNTIF(E43:E72,1) + COUNTIF(G43:G72,1) -> 0
C78: Total fail | D78: =COUNTIF(F43:F72,1) + COUNTIF(H43:H72,1) + COUNTIF(I43:I72,1) + COUNTIF(J43:J72,1) -> 0
C79: Total pellet to box | D79: =COUNTIF(F43:F72,1) + COUNTIF(H43:H72,1) -> 0
C80: Total grasps | D80: =COUNTIF(F43:F72,1) + COUNTIF(E43:E72,1) + COUNTIF(G43:G72,1) + COUNTIF(H43:H72,1) + COUNTIF(I43:I72,1) + COUNTIF(J43:J72,1) -> 0

Sheet RawData_Rat10
A2: Number | B2: Animal | C2: Stroke-status | D2: Video-number | E2: 1st reach - Pellet to Mouth (success) | F2: 1st reach - Pellet to Box (failure) | G2: 2+ reaches - Pellet to Mouth (success) | H2: 2+ reaches - Pellet to Box (failure) | I2: Failure | J2: Dragging (failure)
A3: 1 | B3: Rat 10 | C3: Baseline
A4: 2 | B4: Rat 10 | C4: Baseline
A5: 3 | B5: Rat 10 | C5: Baseline
A6: 4 | B6: Rat 10 | C6: Baseline
A7: 5 | B7: Rat 10 | C7: Baseline
A8: 6 | B8: Rat 10 | C8: Baseline
A9: 7 | B9: Rat 10 | C9: Baseline
A10: 8 | B10: Rat 10 | C10: Baseline
A11: 9 | B11: Rat 10 | C11: Baseline
A12: 10 | B12: Rat 10 | C12: Baseline
A13: 11 | B13: Rat 10 | C13: Baseline
A14: 12 | B14: Rat 10 | C14: Baseline
... A33: 31 | B33: Rat 10 | C33: Baseline
C36: First trial success | D36: =COUNTIF(E3:E33,1) -> 0
C37: Total success | D37: =COUNTIF(E3:E33,1) + COUNTIF(G3:G33,1) -> 0
C38: Total fail | D38: =COUNTIF(F3:F33,1) + COUNTIF(H3:H33,1) + COUNTIF(I3:I33,1) + COUNTIF(J3:J33,1) -> 0
C39: Total pellet to box | D39: =COUNTIF(F3:F33,1) + COUNTIF(H3:H33,1) -> 0
C40: Total grasps | D40: =COUNTIF(F3:F33,1) + COUNTIF(E3:E33,1) + COUNTIF(G3:G33,1) + COUNTIF(H3:H33,1) + COUNTIF(I3:I33,1) + COUNTIF(J3:J33,1) -> 0
A42: Number | B42: Animal | C42: Stroke-status | D42: Video-number | E42: 1st reach - Pellet to Mouth (success) | F42: 1st reach - Pellet to Box (failure) | G42: 2+ reaches - Pellet to Mouth (success) | H42: 2+ reaches - Pellet to Box (failure) | I42: Failure | J42: Dragging (failure)
A43: 1 | B43: Rat 10 | C43: 3 days post stroke
A44: 2 | B44: Rat 10 | C44: 3 days post stroke
A45: 3 | B45: Rat 10 | C45: 3 days post stroke
A46: 4 | B46: Rat 10 | C46: 3 days post stroke
A47: 5 | B47: Rat 10 | C47: 3 days post stroke
A48: 6 | B48: Rat 10 | C48: 3 days post stroke
A49: 7 | B49: Rat 10 | C49: 3 days post stroke
A50: 8 | B50: Rat 10 | C50: 3 days post stroke
A51: 9 | B51: Rat 10 | C51: 3 days post stroke
A52: 10 | B52: Rat 10 | C52: 3 days post stroke
A53: 11 | B53: Rat 10 | C53: 3 days post stroke
A54: 12 | B54: Rat 10 | C54: 3 days post stroke
... A72: 30 | B72: Rat 10 | C72: 3 days post stroke
C76: First trial success | D76: =COUNTIF(E43:E72,1) -> 0
C77: Total success | D77: =COUNTIF(E43:E72,1) + COUNTIF(G43:G72,1) -> 0
C78: Total fail | D78: =COUNTIF(F43:F72,1) + COUNTIF(H43:H72,1) + COUNTIF(I43:I72,1) + COUNTIF(J43:J72,1) -> 0
C79: Total pellet to box | D79: =COUNTIF(F43:F72,1) + COUNTIF(H43:H72,1) -> 0
C80: Total grasps | D80: =COUNTIF(F43:F72,1) + COUNTIF(E43:E72,1) + COUNTIF(G43:G72,1) + COUNTIF(H43:H72,1) + COUNTIF(I43:I72,1) + COUNTIF(J43:J72,1) -> 0

Sheet RawData_Rat11
A2: Number | B2: Animal | C2: Stroke-status | D2: Video-number | E2: 1st reach - Pellet to Mouth (success) | F2: 1st reach - Pellet to Box (failure) | G2: 2+ reaches - Pellet to Mouth (success) | H2: 2+ reaches - Pellet to Box (failure) | I2: Failure | J2: Dragging (failure)
A3: 1 | B3: Rat 11 | C3: Baseline | D3: Basler_acA720-520uc__40502463__20250507_094627168 | F3: 1
A4: 2 | B4: Rat 11 | C4: Baseline | D4: Basler_acA720-520uc__40502463__20250507_094927363 | F4: 1
A5: 3 | B5: Rat 11 | C5: Baseline | D5: Basler_acA720-520uc__40502463__20250507_095252698 | G5: 1
A6: 4 | B6: Rat 11 | C6: Baseline | D6: Basler_acA720-520uc__40502463__20250507_095338367 | I6: 1
A7: 5 | B7: Rat 11 | C7: Baseline | D7: Basler_acA720-520uc__40502463__20250507_095449561 | I7: 1
A8: 6 | B8: Rat 11 | C8: Baseline | D8: Basler_acA720-520uc__40502463__20250507_095513667 | E8: 1
A9: 7 | B9: Rat 11 | C9: Baseline | D9: Basler_acA720-520uc__40502463__20250507_095527402 | I9: 1
A10: 8 | B10: Rat 11 | C10: Baseline | D10: Basler_acA720-520uc__40502463__20250507_095609736 | I10: 1
A11: 9 | B11: Rat 11 | C11: Baseline | D11: Basler_acA720-520uc__40502463__20250507_095720587 | I11: 1
A12: 10 | B12: Rat 11 | C12: Baseline | D12: Basler_acA720-520uc__40502463__20250507_095738003 | I12: 1
A13: 11 | B13: Rat 11 | C13: Baseline | D13: Basler_acA720-520uc__40502463__20250507_100113128 | I13: 1
A14: 12 | B14: Rat 11 | C14: Baseline | D14: Basler_acA720-520uc__40502463__20250507_100206995 | I14: 1
A15: 13 | B15: Rat 11 | C15: Baseline | D15: Basler_acA720-520uc__40502463__20250507_100300825 | I15: 1
A16: 14 | B16: Rat 11 | C16: Baseline | D16: Basler_acA720-520uc__40502463__20250507_100402312 | H16: 1
A17: 15 | B17: Rat 11 | C17: Baseline | D17: Basler_acA720-520uc__40502463__20250507_100440970 | I17: 1
A18: 16 | B18: Rat 11 | C18: Baseline | D18: Basler_acA720-520uc__40502463__20250507_100455441 | G18: 1
A19: 17 | B19: Rat 11 | C19: Baseline | D19: Basler_acA720-520uc__40502463__20250507_100516044 | I19: 1
A20: 18 | B20: Rat 11 | C20: Baseline | D20: Basler_acA720-520uc__40502463__20250507_100529963 | G20: 1
A21: 19 | B21: Rat 11 | C21: Baseline | D21: Basler_acA720-520uc__40502463__20250507_100555387 | I21: 1
A22: 20 | B22: Rat 11 | C22: Baseline | D22: Basler_acA720-520uc__40502463__20250507_100604680 | E22: 1
A23: 21 | B23: Rat 11 | C23: Baseline | D23: Basler_acA720-520uc__40502463__20250507_100618679 | I23: 1
A24: 22 | B24: Rat 11 | C24: Baseline | D24: Basler_acA720-520uc__40502463__20250507_100627475 | G24: 1
A25: 23 | B25: Rat 11 | C25: Baseline | D25: Basler_acA720-520uc__40502463__20250507_100700612 | I25: 1
A26: 24 | B26: Rat 11 | C26: Baseline | D26: Basler_acA720-520uc__40502463__20250507_100736068 | E26: 1
A27: 25 | B27: Rat 11 | C27: Baseline | D27: Basler_acA720-520uc__40502463__20250507_100753984 | I27: 1
A28: 26 | B28: Rat 11 | C28: Baseline | D28: Basler_acA720-520uc__40502463__20250507_100804259 | I28: 1
A29: 27 | B29: Rat 11 | C29: Baseline | D29: Basler_acA720-520uc__40502463__20250507_100823869 | E29: 1
A30: 28 | B30: Rat 11 | C30: Baseline | D30: Basler_acA720-520uc__40502463__20250507_100847650 | I30: 1
A31: 29 | B31: Rat 11 | C31: Baseline | D31: Basler_acA720-520uc__40502463__20250507_100902611 | I31: 1
A32: 30 | B32: Rat 11 | C32: Baseline | D32: Basler_acA720-520uc__40502463__20250507_100914859 | I32: 1
C36: First trial success | D36: =COUNTIF(E3:E33,1) -> 4 | E36: =COUNTIF(E3:E22,1) -> 2
C37: Total success | D37: =COUNTIF(E3:E33,1) + COUNTIF(G3:G33,1) -> 8 | E37: =COUNTIF(E3:E22,1) + COUNTIF(G3:G22,1) -> 5
C38: Total fail | D38: =COUNTIF(F3:F33,1) + COUNTIF(H3:H33,1) + COUNTIF(I3:I33,1) + COUNTIF(J3:J33,1) -> 22 | E38: =COUNTIF(F3:F22,1) + COUNTIF(H3:H22,1) + COUNTIF(I3:I22,1) + COUNTIF(J3:J22,1) -> 15
C39: Total pellet to box | D39: =COUNTIF(F3:F33,1) + COUNTIF(H3:H33,1) -> 3 | E39: =COUNTIF(F3:F22,1) + COUNTIF(H3:H22,1) -> 3
C40: Total grasps | D40: =COUNTIF(F3:F33,1) + COUNTIF(E3:E33,1) + COUNTIF(G3:G33,1) + COUNTIF(H3:H33,1) + COUNTIF(I3:I33,1) + COUNTIF(J3:J33,1) -> 30 | E40: =COUNTIF(E3:E22,1) + COUNTIF(F3:F22,1) + COUNTIF(G3:G22,1) + COUNTIF(H3:H22,1) + COUNTIF(K3:K22,1) + COUNTIF(J3:J22,1) + COUNTIF(I3:I22,1) -> 20
A42: Number | B42: Animal | C42: Stroke-status | D42: Video-number | E42: 1st reach - Pellet to Mouth (success) | F42: 1st reach - Pellet to Box (failure) | G42: 2+ reaches - Pellet to Mouth (success) | H42: 2+ reaches - Pellet to Box (failure) | I42: Failure | J42: Dragging (failure)
A43: 1 | B43: Rat 11 | C43: 3 days post stroke | D43: Basler_acA720-520uc__40502463__20250515_095156411 | I43: 1
A44: 2 | B44: Rat 11 | C44: 3 days post stroke | D44: Basler_acA720-520uc__40502463__20250515_095400146 | I44: 1
A45: 3 | B45: Rat 11 | C45: 3 days post stroke | D45: Basler_acA720-520uc__40502463__20250515_095420590 | E45: 1
...

Sheet RawData_Rat12
A2: Number | B2: Animal | C2: Stroke-status | D2: Video-number | E2: 1st reach - Pellet to Mouth (success) | F2: 1st reach - Pellet to Box (failure) | G2: 2+ reaches - Pellet to Mouth (success) | H2: 2+ reaches - Pellet to Box (failure) | I2: Failure | J2: Dragging (failure)
A3: 1 | B3: Rat 12 | C3: Baseline | D3: Basler_acA720-520uc__40502463__20250514_095908557 | I3: 1
A4: 2 | B4: Rat 12 | C4: Baseline | D4: Basler_acA720-520uc__40502463__20250514_100127700 | H4: 1
A5: 3 | B5: Rat 12 | C5: Baseline | D5: Basler_acA720-520uc__40502463__20250514_100157763 | I5: 1
A6: 4 | B6: Rat 12 | C6: Baseline | D6: Basler_acA720-520uc__40502463__20250514_100241943 | I6: 1
A7: 5 | B7: Rat 12 | C7: Baseline | D7: Basler_acA720-520uc__40502463__20250514_100302699 | I7: 1
A8: 6 | B8: Rat 12 | C8: Baseline | D8: Basler_acA720-520uc__40502463__20250514_100334543 | I8: 1
A9: 7 | B9: Rat 12 | C9: Baseline | D9: Basler_acA720-520uc__40502463__20250514_100347884 | I9: 1
A10: 8 | B10: Rat 12 | C10: Baseline | D10: Basler_acA720-520uc__40502463__20250514_100541420 | I10: 1
A11: 9 | B11: Rat 12 | C11: Baseline | D11: Basler_acA720-520uc__40502463__20250514_100645045 | I11: 1
A12: 10 | B12: Rat 12 | C12: Baseline | D12: Basler_acA720-520uc__40502463__20250514_100707504 | I12: 1
A13: 11 | B13: Rat 12 | C13: Baseline | D13: Basler_acA720-520uc__40502463__20250514_100731166 | I13: 1
A14: 12 | B14: Rat 12 | C14: Baseline | D14: Basler_acA720-520uc__40502463__20250514_100751763 | I14: 1
A15: 13 | B15: Rat 12 | C15: Baseline | D15: Basler_acA720-520uc__40502463__20250514_100942113 | I15: 1
A16: 14 | B16: Rat 12 | C16: Baseline | D16: Basler_acA720-520uc__40502463__20250514_101144071 | I16: 1
A17: 15 | B17: Rat 12 | C17: Baseline | D17: Basler_acA720-520uc__40502463__20250514_101334017 | G17: 1
A18: 16 | B18: Rat 12 | C18: Baseline | D18: Basler_acA720-520uc__40502463__20250514_101603541 | I18: 1
A19: 17 | B19: Rat 12 | C19: Baseline | D19: Basler_acA720-520uc__40502463__20250514_101641249 | I19: 1
A20: 18 | B20: Rat 12 | C20: Baseline | D20: Basler_acA720-520uc__40502463__20250514_101709468 | I20: 1
A21: 19 | B21: Rat 12 | C21: Baseline | D21: Basler_acA720-520uc__40502463__20250514_101909530 | I21: 1
A22: 20 | B22: Rat 12 | C22: Baseline | D22: Basler_acA720-520uc__40502463__20250514_102224630 | I22: 1
A23: 21 | B23: Rat 12 | C23: Baseline | D23: Basler_acA720-520uc__40502463__20250514_102546010 | G23: 1
A24: 22 | B24: Rat 12 | C24: Baseline | D24: Basler_acA720-520uc__40502463__20250514_102944255 | G24: 1
A25: 23 | B25: Rat 12 | C25: Baseline | D25: Basler_acA720-520uc__40502463__20250514_103015417 | I25: 1
A26: 24 | B26: Rat 12 | C26: Baseline | D26: Basler_acA720-520uc__40502463__20250514_103036555 | I26: 1
A27: 25 | B27: Rat 12 | C27: Baseline | D27: Basler_acA720-520uc__40502463__20250514_103355315 | I27: 1
A28: 26 | B28: Rat 12 | C28: Baseline | D28: Basler_acA720-520uc__40502463__20250514_103623223 | I28: 1
A29: 27 | B29: Rat 12 | C29: Baseline | D29: Basler_acA720-520uc__40502463__20250514_103228385 | I29: 1
A30: 28 | B30: Rat 12 | C30: Baseline
A31: 29 | B31: Rat 12 | C31: Baseline
A32: 30 | B32: Rat 12 | C32: Baseline
A33: 31 | B33: Rat 12 | C33: Baseline
C36: First trial success | D36: =COUNTIF(E3:E33,1) -> 0 | E36: =COUNTIF(E3:E22,1) -> 0
C37: Total success | D37: =COUNTIF(E3:E33,1) + COUNTIF(G3:G33,1) -> 3 | E37: =COUNTIF(E3:E22,1) + COUNTIF(G3:G22,1) -> 1
C38: Total fail | D38: =COUNTIF(F3:F33,1) + COUNTIF(H3:H33,1) + COUNTIF(I3:I33,1) + COUNTIF(J3:J33,1) -> 24 | E38: =COUNTIF(F3:F22,1) + COUNTIF(H3:H22,1) + COUNTIF(I3:I22,1) + COUNTIF(J3:J22,1) -> 19
C39: Total pellet to box | D39: =COUNTIF(F3:F33,1) + COUNTIF(H3:H33,1) -> 1 | E39: =COUNTIF(F3:F22,1) + COUNTIF(H3:H22,1) -> 1
C40: Total grasps | D40: =COUNTIF(F3:F33,1) + COUNTIF(E3:E33,1) + COUNTIF(G3:G33,1) + COUNTIF(H3:H33,1) + COUNTIF(I3:I33,1) + COUNTIF(J3:J33,1) -> 27 | E40: =COUNTIF(E3:E22,1) + COUNTIF(F3:F22,1) + COUNTIF(G3:G22,1) + COUNTIF(H3:H22,1) + COUNTIF(K3:K22,1) + COUNTIF(J3:J22,1) + COUNTIF(I3:I22,1) -> 20
A42: Number | B42: Animal | C42: Stroke-status | D42: Video-number | E42: 1st reach - Pellet to Mouth (success) | F42: 1st reach - Pellet to Box (failure) | G42: 2+ reaches - Pellet to Mouth (success) | H42: 2+ reaches - Pellet to Box (failure) | I42: Failure | J42: Dragging (failure)
A43: 1 | B43: Rat 12 | C43: 3 days post stroke | D43: Basler_acA720-520uc__40502463__20250522_085437808 | I43: 1
A44: 2 | B44: Rat 12 | C44: 3 days post stroke | D44: Basler_acA720-520uc__40502463__20250522_085522951 | I44: 1
...

Sheet RawData_Rat13
A2: Number | B2: Animal | C2: Stroke-status | D2: Video-number | E2: 1st reach - Pellet to Mouth (success) | F2: 1st reach - Pellet to Box (failure) | G2: 2+ reaches - Pellet to Mouth (success) | H2: 2+ reaches - Pellet to Box (failure) | I2: Failure | J2: Dragging (failure)
A3: 1 | B3: Rat 13 | C3: Baseline | D3: Basler_acA720-520uc__40502463__20250618_095816536 | I3: 1
A4: 2 | B4: Rat 13 | C4: Baseline | D4: Basler_acA720-520uc__40502463__20250618_095924866 | I4: 1
A5: 3 | B5: Rat 13 | C5: Baseline | D5: Basler_acA720-520uc__40502463__20250618_100724180 | I5: 1
A6: 4 | B6: Rat 13 | C6: Baseline | D6: Basler_acA720-520uc__40502463__20250618_101553896 | I6: 1
A7: 5 | B7: Rat 13 | C7: Baseline | D7: Basler_acA720-520uc__40502463__20250618_102436991 | I7: 1
A8: 6 | B8: Rat 13 | C8: Baseline | D8: Basler_acA720-520uc__40502463__20250618_102459937 | H8: 1
A9: 7 | B9: Rat 13 | C9: Baseline | D9: Basler_acA720-520uc__40502463__20250618_102526366 | I9: 1
A10: 8 | B10: Rat 13 | C10: Baseline | D10: Basler_acA720-520uc__40502463__20250618_102537338 | G10: 1
A11: 9 | B11: Rat 13 | C11: Baseline | D11: Basler_acA720-520uc__40502463__20250618_102621308 | H11: 1
A12: 10 | B12: Rat 13 | C12: Baseline | D12: Basler_acA720-520uc__40502463__20250618_102648950 | I12: 1
A13: 11 | B13: Rat 13 | C13: Baseline | D13: Basler_acA720-520uc__40502463__20250618_102804505 | I13: 1
A14: 12 | B14: Rat 13 | C14: Baseline | D14: Basler_acA720-520uc__40502463__20250618_103902965 | I14: 1
A15: 13 | B15: Rat 13 | C15: Baseline | D15: Basler_acA720-520uc__40502463__20250618_104115160 | I15: 1
A16: 14 | B16: Rat 13 | C16: Baseline | D16: Basler_acA720-520uc__40502463__20250618_104157406 | I16: 1
